<?xml version="1.0"?>
<robot name="inmoov_v1">
  <!--  -->

  <!-- Materials -->
  <material name="red">
    <color rgba="1 0 0 .8"/>
  </material>
  <material name="orange">
    <color rgba="1 .5 0 .8"/>
  </material>
  <material name="yellow">
    <color rgba="1 1 0 .8"/>
  </material>
  <material name="green">
    <color rgba="0 1 0 .8"/>
  </material>
  <material name="blue">
    <color rgba="0 0 1 .8"/>
  </material>
  <material name="indigo">
    <color rgba=".294 0 .510 .8"/>
  </material>
  <material name="violet">
    <color rgba=".561 0 1 .8"/>
  </material>
  <!-- Variables  -->
  <property name="pi" value="3.1415926"/>  
  <property name="pi" value="3.1415926"/> 
  
  <!-- Body Parts -->
  <!-- Base -->
  <link name="base_link">
    <visual>
      <origin rpy="0 0 0" xyz="0 0 0"/>
      <geometry>
        <box size=".4 .1 .1"/>
      </geometry>
      <material name="red"/>
    </visual>
    <collision>
      <geometry>
        <box size=".4 .1 .1"/>
      </geometry>
    </collision>
  </link>
  <!-- 1st shoulder part - up/down -->
  <link name="shoulder_a_link">
    <visual>
      <origin rpy="${pi/2} 0 0" xyz=".025 0 -.05"/>
      <geometry>
        <box size=".05 .1 .1"/>
      </geometry>      
      <material name="orange"/>
    </visual>
    <collision>
      <geometry>
        <box size=".045 .095 .095"/>
      </geometry>
    </collision>
  </link>
  <joint name="arm_out_joint" type="revolute">
    <axis xyz="0 -1 0"/>
    <origin rpy="0 0 0" xyz=".2 0 .05"/>
    <limit effort="1000.0" lower="0.0" upper="${pi/2}" velocity="0.5"/>
    <parent link="base_link"/>
    <child link="shoulder_a_link"/>
  </joint>
  <!-- 2nd shoulder part - fwd/back -->
  <link name="shoulder_b_link">
    <visual>
      <origin rpy="0 0 0" xyz=".05 0 0"/>
      <geometry>
        <box size=".1 .1 .1"/>
      </geometry>      
      <material name="yellow"/>
    </visual>
    <collision>
      <geometry>
        <box size=".095 .095 .095"/>
      </geometry>
    </collision>
  </link>
  <joint name="arm_fwd_joint" type="revolute">
    <axis xyz="1 0 0"/>
    <origin rpy="0 0 0" xyz=".05 0 -0.05"/>
    <limit effort="1000.0" lower="0.0" upper="${pi/2}" velocity="0.5"/>
    <parent link="shoulder_a_link"/>
    <child link="shoulder_b_link"/>
  </joint>
  <!-- biceps -->
  <link name="biceps_link">
    <visual>
      <origin rpy="0 0 0" xyz="0 0 -.15"/>
      <geometry>        
        <cylinder length="0.3" radius="0.05"/>
      </geometry>      
      <material name="green"/>
    </visual>
    <collision>
      <geometry>        
        <cylinder length="0.295" radius="0.05"/>
      </geometry>
    </collision>
  </link>
  <joint name="arm_rotate_joint" type="revolute">
    <axis xyz="0 0 1"/>
    <origin rpy="0 0 0" xyz=".05 0 -.05"/>
    <limit effort="1000.0" lower="${-1*pi/2}" upper="${1*pi/2}" velocity="0.5"/>
    <parent link="shoulder_b_link"/>
    <child link="biceps_link"/>
  </joint>
 <!-- forearm -->
  <link name="forearm_link">
    <visual>
      <origin rpy="0 0 0" xyz="0 0 -.15"/>
      <geometry>
        <cylinder length="0.3" radius="0.05"/>
      </geometry>      
      <material name="blue"/>
    </visual>
    <collision>
      <origin rpy="0 0 0" xyz="0 0 -.175"/>
      <geometry>
        <cylinder length="0.245" radius="0.05"/>
      </geometry>
    </collision>
  </link>
  <joint name="elbow_joint" type="revolute">
    <axis xyz="1 0 0"/>
    <origin rpy="0 0 0" xyz="0 0 -.3"/>
    <limit effort="1000.0" lower="0.0" upper="${pi/2}" velocity="0.5"/>
    <parent link="biceps_link"/>
    <child link="forearm_link"/>
  </joint>
  <!-- wrist -->
  <link name="wrist_link">
    <visual>
      <origin rpy="0 0 0" xyz="0 0 -0.025"/>
      <geometry>        
        <cylinder length="0.05" radius="0.05"/>
      </geometry>      
      <material name="indigo"/>
    </visual>
    <collision>
      <geometry>        
        <cylinder length="0.045" radius="0.05"/>
      </geometry>     
    </collision>
  </link>
  <joint name="wrist_joint" type="revolute">
    <axis xyz="0 0 1"/>
    <origin rpy="0 0 0" xyz="0 0 -.3"/>
    <limit effort="1000.0" lower="${-1*pi/2}" upper="${1*pi/2}" velocity="0.5"/>
    <parent link="forearm_link"/>
    <child link="wrist_link"/>
  </joint>
  <!-- LEFT GRIPPER -->
    <!-- Main -->
  <link name="left_gripper_link">
    <visual>
      <origin rpy="${pi/2} ${pi/2} 0" xyz="0 0 0"/>
      <geometry>
        <mesh filename="package://pr2_description/meshes/gripper_v0/l_finger.dae"/>
        <!--box size=".13 .05 .025"/-->
      </geometry>
      <material name="violet"/>
    </visual>
    <collision>
      <origin rpy="${pi/2} ${pi/2} 0" xyz="0 0 -.075"/>
      <geometry>        
        <box size=".13 .05 .025"/>
      </geometry>
    </collision>
  </link>
  <joint name="left_gripper_joint" type="revolute">
    <axis xyz="0 -1 0"/>
    <origin rpy="0 0 0" xyz=".04 0 -.05"/>
    <limit effort="1000.0" lower="0.0" upper="${pi/2}" velocity="0.5"/>    
    <parent link="wrist_link"/>
    <child link="left_gripper_link"/>
  </joint>
    <!-- Sub -->
  <link name="left_tip_link">
    <visual>
      <origin rpy="${pi/2} ${pi/2} 0 " xyz="-.02 0 -.11"/>
      <geometry>
        <mesh filename="package://pr2_description/meshes/gripper_v0/l_finger_tip.dae"/>
      </geometry>
      <material name="violet"/>
    </visual>
  </link>
  <joint name="left_tip_joint" type="fixed">
    <parent link="left_gripper_link"/>
    <child link="left_tip_link"/>
  </joint>  
  <!-- RIGHT GRIPPER -->
    <!-- Main -->
  <link name="right_gripper_link">
    <visual>
      <origin rpy="${-1*pi/2} ${pi/2} 0" xyz="0 0 0"/>
      <geometry>
        <mesh filename="package://pr2_description/meshes/gripper_v0/l_finger.dae"/>
        <!--box size=".13 .05 .025"/-->
      </geometry>
      <material name="violet"/>
    </visual>
    <collision>
      <origin rpy="${-1*pi/2} ${pi/2} 0" xyz="0 0 -.075"/>
      <geometry>
        <box size=".13 .05 .025"/>
      </geometry>
    </collision>
  </link>
  <joint name="right_gripper_joint" type="revolute">
    <axis xyz="0 1 0"/>
    <origin rpy="0 0 0" xyz="-.04 0 -.05"/>
    <limit effort="1000.0" lower="0.0" upper="${pi/2}" velocity="0.5"/>    
    <parent link="wrist_link"/>
    <child link="right_gripper_link"/>
  </joint>
    <!-- Sub -->
  <link name="right_tip_link">
    <visual>
      <origin rpy="${-1*pi/2} ${pi/2} 0 " xyz=".02 0 -.11"/>
      <geometry>
        <mesh filename="package://pr2_description/meshes/gripper_v0/l_finger_tip.dae"/>
      </geometry>
      <material name="violet"/>
    </visual>
  </link>
  <joint name="right_tip_joint" type="fixed">
    <parent link="right_gripper_link"/>
    <child link="right_tip_link"/>
  </joint>




</robot>
