<?xml version="1.0" ?>
<!-- =================================================================================== -->
<!-- |    This document was autogenerated by xacro from urdf/CURRENTFILE.urdf          | -->
<!-- |    EDITING THIS FILE BY HAND IS NOT RECOMMENDED                                 | -->
<!-- =================================================================================== -->
<robot name="inmoov_v1" xmlns:xacro="http://ros.org/wiki/xacro">
  <!--  -->
  <!-- Materials -->
  <material name="red">
    <color rgba="1 0 0 .8"/>
  </material>
  <material name="orange">
    <color rgba="1 .5 0 .8"/>
  </material>
  <material name="yellow">
    <color rgba="1 1 0 .8"/>
  </material>
  <material name="green">
    <color rgba="0 1 0 .8"/>
  </material>
  <material name="blue">
    <color rgba="0 0 1 .8"/>
  </material>
  <material name="indigo">
    <color rgba=".294 0 .510 .8"/>
  </material>
  <material name="violet">
    <color rgba=".561 0 1 .8"/>
  </material>
  <!-- Variables  -->
  <!-- Body Parts -->
  <!-- Base -->
  <link name="base_link">
    <visual>
      <origin rpy="0 0 0" xyz="0 0 0"/>
      <geometry>
        <mesh filename="package://robo_description/meshes/Inmoov_Baselink_02.STL" scale="0.001 0.001 0.001"/>
      </geometry>
      <material name="red"/>
    </visual>
    <collision>
      <origin pry="0 0 0" xyz=".152 .01 0"/>
      <geometry>
        <mesh filename="package://robo_description/meshes/Inmoov_Baselink_02.STL" scale="0.001 0.001 0.001"/>
      </geometry>
    </collision>
  </link>
  <!-- 1st shoulder part - up/down -->
  <link name="shoulder_a_link">
    <visual>
      <origin rpy="0 0 0" xyz="0 0 0"/>
      <geometry>
        <!--<box size=".05 .1 .1"/>-->
        <mesh filename="package://robo_description/meshes/Inmoov_ShoulderA_02.STL" scale="0.001 0.001 0.001"/>
      </geometry>
      <material name="orange"/>
    </visual>
    <collision>
      <geometry>
        <box size=".045 .095 .095"/>
      </geometry>
    </collision>
  </link>
  <joint name="arm_out_joint" type="revolute">
    <axis xyz="0 1 0"/>
    <origin rpy="0 0 0" xyz="0 0 0"/>
    <limit effort="1000.0" lower="0.0" upper="1.5707963" velocity="0.5"/>
    <parent link="base_link"/>
    <child link="shoulder_a_link"/>
  </joint>
  <!-- 2nd shoulder part - fwd/back -->
  <link name="shoulder_b_link">
    <visual>
      <origin rpy="0 0 0" xyz="0 0 0"/>
      <geometry>
        <!--<box size=".1 .1 .1"/>-->
        <mesh filename="package://robo_description/meshes/Inmoov_ShoulderB_02.STL" scale="0.001 0.001 0.001"/>
      </geometry>
      <material name="yellow"/>
    </visual>
    <collision>
      <geometry>
        <box size=".095 .095 .095"/>
      </geometry>
    </collision>
  </link>
  <joint name="arm_fwd_joint" type="revolute">
    <axis xyz="-1 0 0"/>
    <origin rpy="0 0 0" xyz="0 0 0"/>
    <limit effort="1000.0" lower="0.0" upper="1.5707963" velocity="0.5"/>
    <parent link="shoulder_a_link"/>
    <child link="shoulder_b_link"/>
  </joint>
  <!-- biceps -->
  <link name="biceps_link">
    <visual>
      <origin rpy="0 0 0" xyz=".0775382 .00106347 .0976646"/>
      <geometry>
        <!--<cylinder length="0.3" radius="0.05"/>-->
        <mesh filename="package://robo_description/meshes/Inmoov_Biceps_02.STL" scale="0.001 0.001 0.001"/>
      </geometry>
      <material name="green"/>
    </visual>
    <collision>
      <geometry>
        <cylinder length="0.295" radius="0.05"/>
      </geometry>
    </collision>
  </link>
  <joint name="arm_rotate_joint" type="revolute">
    <axis xyz="0 0 1"/>
    <origin rpy="0 0 0" xyz="-.0775382 -.00106347 -.0976646"/>
    <limit effort="1000.0" lower="-1.5707963" upper="1.5707963" velocity="0.5"/>
    <parent link="shoulder_b_link"/>
    <child link="biceps_link"/>
  </joint>
  <!-- forearm -->
  <link name="forearm_link">
    <visual>
      <origin rpy="0 0 0" xyz=".078261 -.027094 .322299"/>
      <geometry>
        <!--<cylinder length="0.3" radius="0.05"/>-->
        <mesh filename="package://robo_description/meshes/Inmoov_Forearm_02.STL" scale="0.001 0.001 0.001"/>
      </geometry>
      <material name="blue"/>
    </visual>
    <collision>
      <origin rpy="0 0 0" xyz="0 0 0"/>
      <geometry>
        <cylinder length="0.245" radius="0.05"/>
      </geometry>
    </collision>
  </link>
  <joint name="elbow_joint" type="revolute">
    <axis xyz="-1 0 0"/>
    <origin rpy="0 0 0" xyz="-.0007228 .02815747 -.2246344"/>
    <limit effort="1000.0" lower="0.0" upper="1.5707963" velocity="0.5"/>
    <parent link="biceps_link"/>
    <child link="forearm_link"/>
  </joint>
  <!-- wrist -->
  <link name="wrist_link">
    <visual>
      <!--origin rpy="0 0 0" xyz="-.068289 .03942 -.611017"/-->
      <origin rpy="0 0 0" xyz=".068289 -.03942 .611017"/>
      <geometry>
        <!--cylinder length="0.05" radius="0.05"/-->
        <mesh filename="package://robo_description/meshes/Inmoov_Hand_01.STL" scale="0.001 0.001 0.001"/>
      </geometry>
      <material name="indigo"/>
    </visual>
    <collision>
      <geometry>
        <cylinder length="0.045" radius="0.05"/>
      </geometry>
    </collision>
  </link>
  <joint name="wrist_joint" type="revolute">
    <axis xyz="0 0 1"/>
    <origin rpy="0 0 0" xyz=".009972 .012326 -.288718"/>
    <limit effort="1000.0" lower="0.0" upper="3.1415926" velocity="0.5"/>
    <parent link="forearm_link"/>
    <child link="wrist_link"/>
  </joint>
</robot>

